Workbook

Sheet Portada
B2: Toma de Requerimientos
B3: Sistema de proyección de demanda de repuestos · Inchcape Chile
B6: Proyecto | C6: Proyección de demanda de repuestos para elevar el fill rate de Chile
B7: Cliente | C7: Inchcape Chile · Gerencia de Postventa
B8: Asignatura | C8: PTY4614 Capstone · Ingeniería en Informática · Duoc UC
B9: Metodología | C9: Tradicional (cascada) · ciclo de vida del modelo con CRISP-DM
B10: Equipo | C10: Angelo Henríquez · Tania Aburto · Jorge Cavieres
B11: Documento base | C11: Plan de pruebas de certificación, versión 21-09 (51 casos)
B12: Versión | C12: 1.0 · 27 de septiembre de 2026
B14: Objetivo del negocio
B15: Elevar el fill rate de repuestos de 88% a 90% a diciembre de 2026, mejorando la proyección de demanda que alimenta el plan de compra. Hoy 225.264 SKU tienen forecast activo y solo 6.280 (2,8%) se ajustan manualmente: el resto depende de un forecast con un error cercano al 50%.
B17: Cómo se lee este documento
B18: Como proyecto en cascada, los requerimientos preceden al diseño, a la construcción y a las pruebas. Se presentan en el orden del proceso: cada etapa consume lo que produce la anterior, y la columna «Depende de» lo explicita. Cada requerimiento indica qué casos del plan de pruebas lo verifican, y la hoja Trazabilidad muestra la relación completa en ambos sentidos.
B20: Secuencia del proceso
B21: Etapa | D21: Requerimientos | E21: Casos de prueba | F21: Depende de la etapa
B22: 1 · Ingesta y calidad de datos | D22: =COUNTIF(Requerimientos!$B$6:$B$43,B22) -> 5 | E22: =COUNTIF('Pruebas por requerimiento'!$B$6:$B$59,B22) -> 9 | F22: —
B23: 2 · Preparación de datos | D23: =COUNTIF(Requerimientos!$B$6:$B$43,B23) -> 4 | E23: =COUNTIF('Pruebas por requerimiento'!$B$6:$B$59,B23) -> 9 | F23: 1
B24: 3 · Indicador de nivel de servicio | D24: =COUNTIF(Requerimientos!$B$6:$B$43,B24) -> 1 | E24: =COUNTIF('Pruebas por requerimiento'!$B$6:$B$59,B24) -> 1 | F24: 2
B25: 4 · Modelado y validación | D25: =COUNTIF(Requerimientos!$B$6:$B$43,B25) -> 2 | E25: =COUNTIF('Pruebas por requerimiento'!$B$6:$B$59,B25) -> 2 | F25: 2
B26: 5 · Gobierno del modelo | D26: =COUNTIF(Requerimientos!$B$6:$B$43,B26) -> 3 | E26: =COUNTIF('Pruebas por requerimiento'!$B$6:$B$59,B26) -> 3 | F26: 4
B27: 6 · Proyección de demanda | D27: =COUNTIF(Requerimientos!$B$6:$B$43,B27) -> 5 | E27: =COUNTIF('Pruebas por requerimiento'!$B$6:$B$59,B27) -> 8 | F27: 5
B28: 7 · Simulación de cobertura | D28: =COUNTIF(Requerimientos!$B$6:$B$43,B28) -> 2 | E28: =COUNTIF('Pruebas por requerimiento'!$B$6:$B$59,B28) -> 2 | F28: 6
B29: 8 · Plan de compra | D29: =COUNTIF(Requerimientos!$B$6:$B$43,B29) -> 2 | E29: =COUNTIF('Pruebas por requerimiento'!$B$6:$B$59,B29) -> 4 | F29: 7
B30: 9 · Monitoreo del modelo | D30: =COUNTIF(Requerimientos!$B$6:$B$43,B30) -> 2 | E30: =COUNTIF('Pruebas por requerimiento'!$B$6:$B$59,B30) -> 4 | F30: 5 y 6
B31: 10 · Operación del ciclo mensual | D31: =COUNTIF(Requerimientos!$B$6:$B$43,B31) -> 2 | E31: =COUNTIF('Pruebas por requerimiento'!$B$6:$B$59,B31) -> 2 | F31: 1 a 9
B32: 11 · Seguridad y acceso | D32: =COUNTIF(Requerimientos!$B$6:$B$43,B32) -> 2 | E32: =COUNTIF('Pruebas por requerimiento'!$B$6:$B$59,B32) -> 2 | F32: —
B33: 12 · Transversal · no funcionales | D33: =COUNTIF(Requerimientos!$B$6:$B$43,B33) -> 8 | E33: =COUNTIF('Pruebas por requerimiento'!$B$6:$B$59,B33) -> 8 | F33: Transversal
B35: Interesados
B36: Interesado | C36: Rol en el proyecto | D36: Interés en el sistema
B37: Gerencia de Postventa | C37: Cliente que financia la herramienta | D37: Responde por la meta de fill rate de 90% a diciembre de 2026 y aprueba el alcance.
B38: Jefatura de Repuestos | C38: Usuario de negocio · aprobador | D38: Decide el plan de compra y valida los criterios de aceptación del modelo.
B39: Planificador de demanda | C39: Usuario principal | D39: Opera el ciclo mensual en la aplicación: carga, proyección, simulación y plan.
B40: Comprador | C40: Usuario | D40: Emite el pedido en SAP a partir del plan de compra descargado.
B41: TI Inchcape | C41: Soporte | D41: Provee el ambiente, el acceso a las fuentes de SAP y las políticas de seguridad.
B42: Profesor guía · Duoc UC | C42: Institución | D42: Define los requisitos académicos y evalúa el proyecto.
B44: Restricciones del proyecto
B45: ID | C45: Restricción | F45: Origen
B46: RES-01 | C46: La aplicación se construye en Streamlit y la operan los usuarios de negocio. | F46: Profesor guía
B47: RES-02 | C47: El ciclo de vida de los modelos sigue la metodología CRISP-DM. | F47: Profesor guía
B48: RES-03 | C48: La gestión del proyecto es tradicional (cascada): Carta Gantt y backlog de tareas en Jira. | F48: Profesor guía
...

Sheet Resumen
A1: Resumen de la toma de requerimientos
A2: Indicadores calculados con fórmulas sobre las hojas Requerimientos y Pruebas por requerimiento: se actualizan al cambiar un estado o un resultado.
A4: Requerimientos | C4: Funcionales | E4: No funcionales | G4: Casos de prueba vinculados | I4: Avance de implementación | K4: Casos ejecutados
A5: =COUNTA(Requerimientos!$C$6:$C$43) -> 38 | C5: =COUNTIF(Requerimientos!$F$6:$F$43,"Funcional") -> 30 | E5: =COUNTIF(Requerimientos!$F$6:$F$43,"No funcional") -> 8 | G5: =COUNTA('Pruebas por requerimiento'!$O$6:$O$59) -> 54 | I5: =(COUNTIF(Requerimientos!$P$6:$P$43,"Implementado")+0.5*COUNTIF(Requerimientos!$P$6:$P$43,"Parcial"))/COUNTA(Requerimientos!$C$6:$C$43) -> 0.77631579 | K5: =(COUNTA('Pruebas por requerimiento'!$O$6:$O$59)-COUNTIF('Pruebas por requerimiento'!$O$6:$O$59,"No ejecutado"))/COUNTA('Pruebas por requerimiento'!$O$6:$O$59) -> 0
A6: Avance ponderado: Implementado = 100%, Parcial = 50%, Pendiente = 0%. Los casos ejecutados se cuentan desde la columna Resultado de la hoja de pruebas.
A8: Estado por etapa, en el orden de la secuencia | J8: Estado de implementación por etapa
A9: Etapa | C9: Requerimientos | D9: Implementado | E9: Parcial | F9: Pendiente | G9: Casos de prueba | H9: Avance
A10: 1 · Ingesta y calidad de datos | C10: =COUNTIF(Requerimientos!$B$6:$B$43,A10) -> 5 | D10: =COUNTIFS(Requerimientos!$B$6:$B$43,A10,Requerimientos!$P$6:$P$43,"Implementado") -> 4 | E10: =COUNTIFS(Requerimientos!$B$6:$B$43,A10,Requerimientos!$P$6:$P$43,"Parcial") -> 0 | F10: =COUNTIFS(Requerimientos!$B$6:$B$43,A10,Requerimientos!$P$6:$P$43,"Pendiente") -> 1 | G10: =COUNTIF('Pruebas por requerimiento'!$B$6:$B$59,A10) -> 9 | H10: =IF(C10=0,0,(D10+0.5*E10)/C10) -> 0.8
A11: 2 · Preparación de datos | C11: =COUNTIF(Requerimientos!$B$6:$B$43,A11) -> 4 | D11: =COUNTIFS(Requerimientos!$B$6:$B$43,A11,Requerimientos!$P$6:$P$43,"Implementado") -> 3 | E11: =COUNTIFS(Requerimientos!$B$6:$B$43,A11,Requerimientos!$P$6:$P$43,"Parcial") -> 1 | F11: =COUNTIFS(Requerimientos!$B$6:$B$43,A11,Requerimientos!$P$6:$P$43,"Pendiente") -> 0 | G11: =COUNTIF('Pruebas por requerimiento'!$B$6:$B$59,A11) -> 9 | H11: =IF(C11=0,0,(D11+0.5*E11)/C11) -> 0.875
A12: 3 · Indicador de nivel de servicio | C12: =COUNTIF(Requerimientos!$B$6:$B$43,A12) -> 1 | D12: =COUNTIFS(Requerimientos!$B$6:$B$43,A12,Requerimientos!$P$6:$P$43,"Implementado") -> 1 | E12: =COUNTIFS(Requerimientos!$B$6:$B$43,A12,Requerimientos!$P$6:$P$43,"Parcial") -> 0 | F12: =COUNTIFS(Requerimientos!$B$6:$B$43,A12,Requerimientos!$P$6:$P$43,"Pendiente") -> 0 | G12: =COUNTIF('Pruebas por requerimiento'!$B$6:$B$59,A12) -> 1 | H12: =IF(C12=0,0,(D12+0.5*E12)/C12) -> 1
A13: 4 · Modelado y validación | C13: =COUNTIF(Requerimientos!$B$6:$B$43,A13) -> 2 | D13: =COUNTIFS(Requerimientos!$B$6:$B$43,A13,Requerimientos!$P$6:$P$43,"Implementado") -> 2 | E13: =COUNTIFS(Requerimientos!$B$6:$B$43,A13,Requerimientos!$P$6:$P$43,"Parcial") -> 0 | F13: =COUNTIFS(Requerimientos!$B$6:$B$43,A13,Requerimientos!$P$6:$P$43,"Pendiente") -> 0 | G13: =COUNTIF('Pruebas por requerimiento'!$B$6:$B$59,A13) -> 2 | H13: =IF(C13=0,0,(D13+0.5*E13)/C13) -> 1
A14: 5 · Gobierno del modelo | C14: =COUNTIF(Requerimientos!$B$6:$B$43,A14) -> 3 | D14: =COUNTIFS(Requerimientos!$B$6:$B$43,A14,Requerimientos!$P$6:$P$43,"Implementado") -> 2 | E14: =COUNTIFS(Requerimientos!$B$6:$B$43,A14,Requerimientos!$P$6:$P$43,"Parcial") -> 0 | F14: =COUNTIFS(Requerimientos!$B$6:$B$43,A14,Requerimientos!$P$6:$P$43,"Pendiente") -> 1 | G14: =COUNTIF('Pruebas por requerimiento'!$B$6:$B$59,A14) -> 3 | H14: =IF(C14=0,0,(D14+0.5*E14)/C14) -> 0.66666667
A15: 6 · Proyección de demanda | C15: =COUNTIF(Requerimientos!$B$6:$B$43,A15) -> 5 | D15: =COUNTIFS(Requerimientos!$B$6:$B$43,A15,Requerimientos!$P$6:$P$43,"Implementado") -> 3 | E15: =COUNTIFS(Requerimientos!$B$6:$B$43,A15,Requerimientos!$P$6:$P$43,"Parcial") -> 2 | F15: =COUNTIFS(Requerimientos!$B$6:$B$43,A15,Requerimientos!$P$6:$P$43,"Pendiente") -> 0 | G15: =COUNTIF('Pruebas por requerimiento'!$B$6:$B$59,A15) -> 8 | H15: =IF(C15=0,0,(D15+0.5*E15)/C15) -> 0.8
A16: 7 · Simulación de cobertura | C16: =COUNTIF(Requerimientos!$B$6:$B$43,A16) -> 2 | D16: =COUNTIFS(Requerimientos!$B$6:$B$43,A16,Requerimientos!$P$6:$P$43,"Implementado") -> 2 | E16: =COUNTIFS(Requerimientos!$B$6:$B$43,A16,Requerimientos!$P$6:$P$43,"Parcial") -> 0 | F16: =COUNTIFS(Requerimientos!$B$6:$B$43,A16,Requerimientos!$P$6:$P$43,"Pendiente") -> 0 | G16: =COUNTIF('Pruebas por requerimiento'!$B$6:$B$59,A16) -> 2 | H16: =IF(C16=0,0,(D16+0.5*E16)/C16) -> 1
A17: 8 · Plan de compra | C17: =COUNTIF(Requerimientos!$B$6:$B$43,A17) -> 2 | D17: =COUNTIFS(Requerimientos!$B$6:$B$43,A17,Requerimientos!$P$6:$P$43,"Implementado") -> 1 | E17: =COUNTIFS(Requerimientos!$B$6:$B$43,A17,Requerimientos!$P$6:$P$43,"Parcial") -> 1 | F17: =COUNTIFS(Requerimientos!$B$6:$B$43,A17,Requerimientos!$P$6:$P$43,"Pendiente") -> 0 | G17: =COUNTIF('Pruebas por requerimiento'!$B$6:$B$59,A17) -> 4 | H17: =IF(C17=0,0,(D17+0.5*E17)/C17) -> 0.75
A18: 9 · Monitoreo del modelo | C18: =COUNTIF(Requerimientos!$B$6:$B$43,A18) -> 2 | D18: =COUNTIFS(Requerimientos!$B$6:$B$43,A18,Requerimientos!$P$6:$P$43,"Implementado") -> 1 | E18: =COUNTIFS(Requerimientos!$B$6:$B$43,A18,Requerimientos!$P$6:$P$43,"Parcial") -> 1 | F18: =COUNTIFS(Requerimientos!$B$6:$B$43,A18,Requerimientos!$P$6:$P$43,"Pendiente") -> 0 | G18: =COUNTIF('Pruebas por requerimiento'!$B$6:$B$59,A18) -> 4 | H18: =IF(C18=0,0,(D18+0.5*E18)/C18) -> 0.75
A19: 10 · Operación del ciclo mensual | C19: =COUNTIF(Requerimientos!$B$6:$B$43,A19) -> 2 | D19: =COUNTIFS(Requerimientos!$B$6:$B$43,A19,Requerimientos!$P$6:$P$43,"Implementado") -> 1 | E19: =COUNTIFS(Requerimientos!$B$6:$B$43,A19,Requerimientos!$P$6:$P$43,"Parcial") -> 1 | F19: =COUNTIFS(Requerimientos!$B$6:$B$43,A19,Requerimientos!$P$6:$P$43,"Pendiente") -> 0 | G19: =COUNTIF('Pruebas por requerimiento'!$B$6:$B$59,A19) -> 2 | H19: =IF(C19=0,0,(D19+0.5*E19)/C19) -> 0.75
A20: 11 · Seguridad y acceso | C20: =COUNTIF(Requerimientos!$B$6:$B$43,A20) -> 2 | D20: =COUNTIFS(Requerimientos!$B$6:$B$43,A20,Requerimientos!$P$6:$P$43,"Implementado") -> 0 | E20: =COUNTIFS(Requerimientos!$B$6:$B$43,A20,Requerimientos!$P$6:$P$43,"Parcial") -> 0 | F20: =COUNTIFS(Requerimientos!$B$6:$B$43,A20,Requerimientos!$P$6:$P$43,"Pendiente") -> 2 | G20: =COUNTIF('Pruebas por requerimiento'!$B$6:$B$59,A20) -> 2 | H20: =IF(C20=0,0,(D20+0.5*E20)/C20) -> 0
A21: 12 · Transversal · no funcionales | C21: =COUNTIF(Requerimientos!$B$6:$B$43,A21) -> 8 | D21: =COUNTIFS(Requerimientos!$B$6:$B$43,A21,Requerimientos!$P$6:$P$43,"Implementado") -> 5 | E21: =COUNTIFS(Requerimientos!$B$6:$B$43,A21,Requerimientos!$P$6:$P$43,"Parcial") -> 3 | F21: =COUNTIFS(Requerimientos!$B$6:$B$43,A21,Requerimientos!$P$6:$P$43,"Pendiente") -> 0 | G21: =COUNTIF('Pruebas por requerimiento'!$B$6:$B$59,A21) -> 8 | H21: =IF(C21=0,0,(D21+0.5*E21)/C21) -> 0.8125
A22: Total | C22: =SUM(C10:C21) -> 38 | D22: =SUM(D10:D21) -> 25 | E22: =SUM(E10:E21) -> 9 | F22: =SUM(F10:F21) -> 4 | G22: =SUM(G10:G21) -> 54 | H22: =IF(C22=0,0,(D22+0.5*E22)/C22) -> 0.77631579
A24: Estado por prioridad
A25: Prioridad | C25: Requerimientos | D25: Implementado | E25: Parcial | F25: Pendiente
A26: Alta | C26: =COUNTIF(Requerimientos!$H$6:$H$43,A26) -> 28 | D26: =COUNTIFS(Requerimientos!$H$6:$H$43,A26,Requerimientos!$P$6:$P$43,"Implementado") -> 21 | E26: =COUNTIFS(Requerimientos!$H$6:$H$43,A26,Requerimientos!$P$6:$P$43,"Parcial") -> 6 | F26: =COUNTIFS(Requerimientos!$H$6:$H$43,A26,Requerimientos!$P$6:$P$43,"Pendiente") -> 1
A27: Media | C27: =COUNTIF(Requerimientos!$H$6:$H$43,A27) -> 9 | D27: =COUNTIFS(Requerimientos!$H$6:$H$43,A27,Requerimientos!$P$6:$P$43,"Implementado") -> 4 | E27: =COUNTIFS(Requerimientos!$H$6:$H$43,A27,Requerimientos!$P$6:$P$43,"Parcial") -> 2 | F27: =COUNTIFS(Requerimientos!$H$6:$H$43,A27,Requerimientos!$P$6:$P$43,"Pendiente") -> 3
A28: Baja | C28: =COUNTIF(Requerimientos!$H$6:$H$43,A28) -> 1 | D28: =COUNTIFS(Requerimientos!$H$6:$H$43,A28,Requerimientos!$P$6:$P$43,"Implementado") -> 0 | E28: =COUNTIFS(Requerimientos!$H$6:$H$43,A28,Requerimientos!$P$6:$P$43,"Parcial") -> 1 | F28: =COUNTIFS(Requerimientos!$H$6:$H$43,A28,Requerimientos!$P$6:$P$43,"Pendiente") -> 0
A30: Cobertura de pruebas
A31: Requerimientos cubiertos por el plan 21-09 | F31: =COUNTIF(Trazabilidad!$BG$6:$BG$43,"Cubierto") -> 35
A32: Requerimientos cubiertos solo con caso propuesto | F32: =COUNTIF(Trazabilidad!$BG$6:$BG$43,"Con caso propuesto") -> 3
A33: Casos del plan 21-09 | F33: =COUNTIF('Pruebas por requerimiento'!$Q$6:$Q$59,"Plan 21-09") -> 51
A34: Casos propuestos | F34: =COUNTIF('Pruebas por requerimiento'!$Q$6:$Q$59,"Propuesto") -> 3

Sheet Requerimientos
A1: Toma de requerimientos
A2: Requerimientos funcionales y no funcionales en la secuencia lógica del proceso. Cada uno declara de qué requerimiento depende y qué casos del plan de pruebas lo verifican.
A3: Casos de prueba: principal = el caso verifica el requerimiento · adicional = lo ejercita dentro de una prueba E2E o de aceptación. Estado verificado contra el código del repositorio al 27-09-2026.
A5: Nº | B5: Etapa | C5: ID | D5: Requerimiento | E5: Descripción | F5: Tipo | G5: Característica ISO/IEC 25010 | H5: Prioridad | I5: Solicitante | J5: Usuario | K5: Depende de | L5: Criterio de aceptación | M5: Casos de prueba (principal) | N5: Casos de prueba (adicional) | O5: Implementación | P5: Estado | Q5: Observaciones
A6: 1 | B6: 1 · Ingesta y calidad de datos | C6: RF-01 | D6: Cargar las fuentes del ciclo mensual | E6: El sistema debe permitir cargar las fuentes del mes —venta, pedidos, forecast del ciclo S&OP, stock, tránsito, maestro de materiales, cadena de reemplazo y parque vehicular— y mostrar al término la fecha de carga y la cantidad de registros procesados. | F6: Funcional | G6: Adecuación funcional | H6: Alta | I6: Planificación de demanda | J6: Planificador de demanda | K6: — | L6: El resumen en pantalla coincide con la cantidad de filas de los archivos de origen. | M6: MTC_0010 | N6: MTC_00110 MTC_00470 | O6: Módulo 1 · Carga de datos apt.pipeline.carga | P6: Implementado | Q6: 138.960 registros cargados en 0,86 s sobre el conjunto sintético.
A7: 2 | B7: 1 · Ingesta y calidad de datos | C7: RF-02 | D7: Validar la estructura de los archivos | E7: El sistema debe verificar que cada archivo tenga registros y todas sus columnas obligatorias antes de procesarlo. Si no las tiene, debe rechazarlo, informar qué columnas faltan y no persistir ningún registro. | F7: Funcional | G7: Adecuación funcional | H7: Alta | I7: Planificación de demanda | J7: Sistema (proceso automático) | K7: RF-01 | L7: El mensaje nombra las columnas ausentes y la base de datos no queda alterada. | M7: MTC_0020 MTC_0030 | N7: — | O7: Módulo 1 · Carga de datos apt.pipeline.validacion | P7: Implementado | Q7: Reglas «archivo no vacío» y «columnas obligatorias», con severidad ERROR que detiene la carga.
A8: 3 | B8: 1 · Ingesta y calidad de datos | C8: RF-03 | D8: Aplicar las reglas de calidad de datos | E8: El sistema debe detectar registros duplicados, cantidades negativas, períodos sin venta y materiales inexistentes en el maestro; registrar cada hallazgo en el log de calidad, aplicar la regla acordada y continuar con el resto del archivo. | F8: Funcional | G8: Adecuación funcional | H8: Alta | I8: Planificación de demanda | J8: Sistema (proceso automático) | K8: RF-02 | L8: El log informa la cantidad exacta de hallazgos por regla y la acción aplicada. Ningún registro negativo llega al set de entrenamiento. | M8: MTC_0040 MTC_0050 MTC_0060 MTC_0070 | N8: — | O8: Módulo 1 · Carga de datos apt.pipeline.validacion | P8: Implementado | Q8: 15 reglas con severidad OK, ADVERTENCIA o ERROR.
A9: 4 | B9: 1 · Ingesta y calidad de datos | C9: RF-04 | D9: Controlar la recarga de un período ya procesado | E9: El sistema debe advertir cuando se intenta cargar un período que ya fue procesado y solicitar confirmación explícita antes de sobrescribirlo. | F9: Funcional | G9: Adecuación funcional | H9: Media | I9: Planificación de demanda | J9: Planificador de demanda | K9: RF-01 | L9: Sin confirmación explícita del usuario, la carga existente no se modifica. | M9: MTC_00100 | N9: — | O9: Módulo 1 · Carga de datos apt.pipeline.carga | P9: Pendiente | Q9: El pipeline ya es idempotente: reprocesar un mes no duplica datos. Falta la advertencia y la confirmación en la interfaz.
A10: 5 | B10: 1 · Ingesta y calidad de datos | C10: RF-05 | D10: Registrar la trazabilidad de cada carga | E10: El sistema debe registrar por cada carga la fecha, el usuario, el volumen leído y cargado por fuente y el resultado de cada regla de validación. | F10: Funcional | G10: Adecuación funcional | H10: Alta | I10: Jefatura de Repuestos | J10: Sistema (proceso automático) | K10: RF-03 | L10: El registro permite reconstruir qué datos alimentaron cada proyección publicada. | M10: MTC_00120 | N10: MTC_00510 | O10: Módulo 1 · Carga de datos apt.pipeline.carga · ops.log_carga | P10: Implementado | Q10: Bitácora de cargas en log_cargas.jsonl y en la tabla ops.log_carga del modelo físico.
A11: 6 | B11: 2 · Preparación de datos | C11: RF-06 | D11: Normalizar cada material a su último eslabón vigente | E11: El sistema debe resolver la cadena de reemplazo de cada código hasta su último eslabón vigente y consolidar bajo él la venta de sus antecesores. Un material sin antecesor conserva su propio código. | F11: Funcional | G11: Adecuación funcional | H11: Alta | I11: Planificación de demanda | J11: Sistema (proceso automático) | K11: RF-03 | L11: La venta del antecesor se suma a la del código vigente sin duplicar unidades; ningún registro queda con último eslabón vacío y una cadena cíclica se detecta sin bucle infinito. | M11: MTC_0080 MTC_0090 MTC_00420 | N11: MTC_00480 | O11: Pipeline de datos apt.dominio.normalizacion | P11: Implementado | Q11: Es la base para proyectar un código nuevo que reemplaza a otro con historia de venta.
A12: 7 | B12: 2 · Preparación de datos | C12: RF-07 | D12: Calcular las variables históricas de demanda | E12: El sistema debe calcular por material los rezagos de 1, 3, 6 y 12 meses, las medias móviles, la tendencia y la proporción de meses sin venta, usando solo información anterior al período que se proyecta. | F12: Funcional | G12: Adecuación funcional | H12: Alta | I12: Equipo de proyecto | J12: Sistema (proceso automático) | K12: RF-06 | L12: Los valores coinciden con un cálculo manual de control. Un material con menos de 12 meses de historia queda con rezagos nulos y no se descarta del set. | M12: MTC_00140 MTC_00150 MTC_00160 | N12: — | O12: Pipeline de datos apt.dominio.features | P12: Implementado | Q12: Las medias móviles excluyen el período objetivo para evitar fuga de información.
A13: 8 | B13: 2 · Preparación de datos | C13: RF-08 | D13: Clasificar cada material según su Apertura Parque | E13: El sistema debe cruzar cada material con el maestro de vigencia y clasificarlo como Vigente, No Vigente o Nuevo. Un material sin clasificación informada recibe el valor por defecto acordado y no se pierde del set. | F13: Funcional | G13: Adecuación funcional | H13: Alta | I13: Planificación de demanda | J13: Sistema (proceso automático) | K13: RF-06 | L13: La clasificación coincide con el maestro para el 100% de los materiales cruzados y el total de materiales no disminuye tras el cruce. | M13: MTC_00170 MTC_00180 | N13: MTC_00250 | O13: Pipeline de datos apt.dominio.features | P13: Parcial | Q13: La clasificación se cruza y se valida contra un dominio cerrado. Falta acordar con el negocio el valor por defecto para materiales sin clasificación.
A14: 9 | B14: 2 · Preparación de datos | C14: RF-09 | D14: Particionar los datos respetando el orden temporal | E14: El sistema debe separar los datos de entrenamiento y de prueba por fecha, de modo que el conjunto de prueba contenga únicamente períodos posteriores a los del entrenamiento. | F14: Funcional | G14: Adecuación funcional | H14: Alta | I14: Equipo de proyecto | J14: Sistema (proceso automático) | K14: RF-07 | L14: Ningún período del conjunto de prueba aparece en el de entrenamiento. | M14: MTC_00190 | N14: — | O14: Pipeline de datos apt.dominio.features | P14: Implementado | Q14: Se reservan los últimos 6 períodos para prueba (parámetro APT_PERIODOS_PRUEBA).
A15: 10 | B15: 3 · Indicador de nivel de servicio | C15: RF-10 | D15: Calcular el fill rate y su brecha contra la meta | E15: El sistema debe calcular el fill rate en líneas y en unidades con las clases de documento de SAP —ZRDP y Z300 como línea atendida, ZVDP y ZVOR como VOR—, abrirlo por marca, familia y segmento, y expresar la brecha contra la meta de 90% en puntos porcentuales y en líneas por recuperar. | F15: Funcional | G15: Adecuación funcional | H15: Alta | I15: Gerencia de Postventa | J15: Gerencia de Postventa | K15: RF-06 | L15: El valor coincide con el reporte de fill rate de SAP del mismo período. Una clase de documento desconocida detiene el cálculo en lugar de omitirse en silencio. | M15: MTC_00590 | N15: — | O15: Resumen apt.dominio.fill_rate | P15: Implementado | Q15: Cubierto por 9 pruebas automatizadas (tests/test_fill_rate.py). No tenía caso en el plan: se propone MTC_00590.
A16: 11 | B16: 4 · Modelado y validación | C16: RF-11 | D16: Medir el error de pronóstico con WMAPE, ERP y ERN | E16: El sistema debe calcular el WMAPE, el error por exceso (ERP) y el error por defecto (ERN) del modelo y del forecast vigente del ciclo S&OP sobre los mismos períodos, sin fallar cuando la venta es cero. | F16: Funcional | G16: Adecuación funcional | H16: Alta | I16: Planificación de demanda | J16: Sistema (proceso automático) | K16: RF-09 | L16: Las tres métricas coinciden con el cálculo manual del caso de control, y el caso con venta cero se maneja sin división por cero. | M16: MTC_00430 | N16: — | O16: Pipeline de modelos apt.dominio.metricas | P16: Implementado | Q16: El ERN es el error que produce quiebre y afecta el fill rate; el ERP solo inmoviliza capital.
A17: 12 | B17: 4 · Modelado y validación | C17: RF-12 | D17: Entrenar y validar los modelos candidatos | E17: El sistema debe entrenar al menos tres modelos candidatos —naive, media móvil y gradient boosting—, evaluarlos con backtesting contra cinco criterios de aceptación y asignar a cada segmento (AA, A, B, C, N) el de menor error. | F17: Funcional | G17: Adecuación funcional | H17: Alta | I17: Profesor guía · Duoc UC | J17: Administrador del sistema | K17: RF-11 | L17: El modelo asignado a cada segmento no tiene un WMAPE mayor que ningún otro candidato en ese segmento. | M17: MTC_00600 | N17: MTC_00490 | O17: Pipeline de modelos apt.modelos.entrenamiento · backtesting | P17: Implementado | Q17: GBM seleccionado en los cinco segmentos: WMAPE 0,3286, 6,4 puntos mejor que el forecast vigente. Cubierto por 13 pruebas automatizadas. Se propone MTC_00600.
... A43: 38 | B43: 12 · Transversal · no funcionales | C43: RNF-08 | D43: Despliegue en contenedores | E43: El sistema debe desplegarse con Docker Compose —aplicación, base de datos PostgreSQL, pipeline y pruebas— con un solo comando y sin credenciales escritas en el código. | F43: No funcional | G43: Portabilidad | H43: Alta | I43: Profesor guía · Duoc UC | J43: Administrador del sistema | K43: — | L43: Ambos servicios quedan en estado healthy y la aplicación responde en el puerto 8501. | M43: MTC_00610 | N43: — | O43: Transversal Dockerfile · docker-compose.yml | P43: Parcial | Q43: Dockerfile de tres etapas y compose con cuatro servicios. Falta verificar la construcción en un equipo con Docker instalado. Se propone MTC_00610.

Sheet Trazabilidad
A1: Matriz de trazabilidad requerimiento–caso de prueba
A2: Los casos están ordenados según la secuencia de los requerimientos: la diagonal muestra que cada etapa se verifica antes de la siguiente.
A3: ● el caso verifica el requerimiento (principal) ○ lo ejercita dentro de una prueba E2E o de aceptación Columnas en amarillo: casos propuestos para cerrar brechas.
A5: ID | B5: Requerimiento | C5: MTC_0010 | D5: MTC_0020 | E5: MTC_0030 | F5: MTC_0040 | G5: MTC_0050 | H5: MTC_0060 | I5: MTC_0070 | J5: MTC_00100 | K5: MTC_00120 | L5: MTC_0080 | M5: MTC_0090 | N5: MTC_00420 | O5: MTC_00140 | P5: MTC_00150 | Q5: MTC_00160 | R5: MTC_00170 | S5: MTC_00180 | T5: MTC_00190 | U5: MTC_00590 | V5: MTC_00430 | W5: MTC_00600 | X5: MTC_00380 | Y5: MTC_00360 | Z5: MTC_00370 | AA5: MTC_00200 | AB5: MTC_00210 | AC5: MTC_00220 | AD5: MTC_00230 | AE5: MTC_00240 | AF5: MTC_00250 | AG5: MTC_00480 | AH5: MTC_00260 | AI5: MTC_00300 | AJ5: MTC_00310 | AK5: MTC_00330 | AL5: MTC_00350 | AM5: MTC_00340 | AN5: MTC_00570 | AO5: MTC_00270 | AP5: MTC_00280 | AQ5: MTC_00580 | AR5: MTC_00490 | AS5: MTC_00470 | AT5: MTC_00510 | AU5: MTC_00390 | AV5: MTC_00400 | AW5: MTC_00520 | AX5: MTC_00540 | AY5: MTC_00550 | AZ5: MTC_00500 | BA5: MTC_00460 | BB5: MTC_00110 | BC5: MTC_00560 | BD5: MTC_00610 | BE5: Casos del plan | BF5: Casos propuestos | BG5: Cobertura
A6: RF-01 | B6: Cargar las fuentes del ciclo mensual | C6: ● | AS6: ○ | BB6: ○ | BE6: =COUNTIF(C6:BD6,"●")-((U6="●")+(W6="●")+(BD6="●")) -> 1 | BF6: =(U6="●")+(W6="●")+(BD6="●") -> 0 | BG6: =IF(BE6>0,"Cubierto",IF(BF6>0,"Con caso propuesto","Sin caso de prueba")) -> Cubierto
A7: RF-02 | B7: Validar la estructura de los archivos | D7: ● | E7: ● | BE7: =COUNTIF(C7:BD7,"●")-((U7="●")+(W7="●")+(BD7="●")) -> 2 | BF7: =(U7="●")+(W7="●")+(BD7="●") -> 0 | BG7: =IF(BE7>0,"Cubierto",IF(BF7>0,"Con caso propuesto","Sin caso de prueba")) -> Cubierto
A8: RF-03 | B8: Aplicar las reglas de calidad de datos | F8: ● | G8: ● | H8: ● | I8: ● | BE8: =COUNTIF(C8:BD8,"●")-((U8="●")+(W8="●")+(BD8="●")) -> 4 | BF8: =(U8="●")+(W8="●")+(BD8="●") -> 0 | BG8: =IF(BE8>0,"Cubierto",IF(BF8>0,"Con caso propuesto","Sin caso de prueba")) -> Cubierto
A9: RF-04 | B9: Controlar la recarga de un período ya procesado | J9: ● | BE9: =COUNTIF(C9:BD9,"●")-((U9="●")+(W9="●")+(BD9="●")) -> 1 | BF9: =(U9="●")+(W9="●")+(BD9="●") -> 0 | BG9: =IF(BE9>0,"Cubierto",IF(BF9>0,"Con caso propuesto","Sin caso de prueba")) -> Cubierto
A10: RF-05 | B10: Registrar la trazabilidad de cada carga | K10: ● | AT10: ○ | BE10: =COUNTIF(C10:BD10,"●")-((U10="●")+(W10="●")+(BD10="●")) -> 1 | BF10: =(U10="●")+(W10="●")+(BD10="●") -> 0 | BG10: =IF(BE10>0,"Cubierto",IF(BF10>0,"Con caso propuesto","Sin caso de prueba")) -> Cubierto
A11: RF-06 | B11: Normalizar cada material a su último eslabón vigente | L11: ● | M11: ● | N11: ● | AG11: ○ | BE11: =COUNTIF(C11:BD11,"●")-((U11="●")+(W11="●")+(BD11="●")) -> 3 | BF11: =(U11="●")+(W11="●")+(BD11="●") -> 0 | BG11: =IF(BE11>0,"Cubierto",IF(BF11>0,"Con caso propuesto","Sin caso de prueba")) -> Cubierto
A12: RF-07 | B12: Calcular las variables históricas de demanda | O12: ● | P12: ● | Q12: ● | BE12: =COUNTIF(C12:BD12,"●")-((U12="●")+(W12="●")+(BD12="●")) -> 3 | BF12: =(U12="●")+(W12="●")+(BD12="●") -> 0 | BG12: =IF(BE12>0,"Cubierto",IF(BF12>0,"Con caso propuesto","Sin caso de prueba")) -> Cubierto
A13: RF-08 | B13: Clasificar cada material según su Apertura Parque | R13: ● | S13: ● | AF13: ○ | BE13: =COUNTIF(C13:BD13,"●")-((U13="●")+(W13="●")+(BD13="●")) -> 2 | BF13: =(U13="●")+(W13="●")+(BD13="●") -> 0 | BG13: =IF(BE13>0,"Cubierto",IF(BF13>0,"Con caso propuesto","Sin caso de prueba")) -> Cubierto
A14: RF-09 | B14: Particionar los datos respetando el orden temporal | T14: ● | BE14: =COUNTIF(C14:BD14,"●")-((U14="●")+(W14="●")+(BD14="●")) -> 1 | BF14: =(U14="●")+(W14="●")+(BD14="●") -> 0 | BG14: =IF(BE14>0,"Cubierto",IF(BF14>0,"Con caso propuesto","Sin caso de prueba")) -> Cubierto
A15: RF-10 | B15: Calcular el fill rate y su brecha contra la meta | U15: ● | BE15: =COUNTIF(C15:BD15,"●")-((U15="●")+(W15="●")+(BD15="●")) -> 0 | BF15: =(U15="●")+(W15="●")+(BD15="●") -> 1 | BG15: =IF(BE15>0,"Cubierto",IF(BF15>0,"Con caso propuesto","Sin caso de prueba")) -> Con caso propuesto
A16: RF-11 | B16: Medir el error de pronóstico con WMAPE, ERP y ERN | V16: ● | BE16: =COUNTIF(C16:BD16,"●")-((U16="●")+(W16="●")+(BD16="●")) -> 1 | BF16: =(U16="●")+(W16="●")+(BD16="●") -> 0 | BG16: =IF(BE16>0,"Cubierto",IF(BF16>0,"Con caso propuesto","Sin caso de prueba")) -> Cubierto
A17: RF-12 | B17: Entrenar y validar los modelos candidatos | W17: ● | AR17: ○ | BE17: =COUNTIF(C17:BD17,"●")-((U17="●")+(W17="●")+(BD17="●")) -> 0 | BF17: =(U17="●")+(W17="●")+(BD17="●") -> 1 | BG17: =IF(BE17>0,"Cubierto",IF(BF17>0,"Con caso propuesto","Sin caso de prueba")) -> Con caso propuesto
A18: RF-13 | B18: Publicar únicamente versiones aprobadas | X18: ● | AR18: ○ | BE18: =COUNTIF(C18:BD18,"●")-((U18="●")+(W18="●")+(BD18="●")) -> 1 | BF18: =(U18="●")+(W18="●")+(BD18="●") -> 0 | BG18: =IF(BE18>0,"Cubierto",IF(BF18>0,"Con caso propuesto","Sin caso de prueba")) -> Cubierto
A19: RF-14 | B19: Mantener el historial de versiones del modelo | Y19: ● | AR19: ○ | AT19: ○ | BE19: =COUNTIF(C19:BD19,"●")-((U19="●")+(W19="●")+(BD19="●")) -> 1 | BF19: =(U19="●")+(W19="●")+(BD19="●") -> 0 | BG19: =IF(BE19>0,"Cubierto",IF(BF19>0,"Con caso propuesto","Sin caso de prueba")) -> Cubierto
A20: RF-15 | B20: Restituir una versión anterior del modelo | Z20: ● | BE20: =COUNTIF(C20:BD20,"●")-((U20="●")+(W20="●")+(BD20="●")) -> 1 | BF20: =(U20="●")+(W20="●")+(BD20="●") -> 0 | BG20: =IF(BE20>0,"Cubierto",IF(BF20>0,"Con caso propuesto","Sin caso de prueba")) -> Cubierto
A21: RF-16 | B21: Consultar la proyección de demanda con filtros | AA21: ● | AB21: ● | AC21: ● | AS21: ○ | BE21: =COUNTIF(C21:BD21,"●")-((U21="●")+(W21="●")+(BD21="●")) -> 3 | BF21: =(U21="●")+(W21="●")+(BD21="●") -> 0 | BG21: =IF(BE21>0,"Cubierto",IF(BF21>0,"Con caso propuesto","Sin caso de prueba")) -> Cubierto
A22: RF-17 | B22: Ordenar la proyección por riesgo de quiebre | AD22: ● | BE22: =COUNTIF(C22:BD22,"●")-((U22="●")+(W22="●")+(BD22="●")) -> 1 | BF22: =(U22="●")+(W22="●")+(BD22="●") -> 0 | BG22: =IF(BE22>0,"Cubierto",IF(BF22>0,"Con caso propuesto","Sin caso de prueba")) -> Cubierto
A23: RF-18 | B23: Exportar el resultado de la consulta | AE23: ● | BE23: =COUNTIF(C23:BD23,"●")-((U23="●")+(W23="●")+(BD23="●")) -> 1 | BF23: =(U23="●")+(W23="●")+(BD23="●") -> 0 | BG23: =IF(BE23>0,"Cubierto",IF(BF23>0,"Con caso propuesto","Sin caso de prueba")) -> Cubierto
A24: RF-19 | B24: Proyectar códigos nuevos sin historial de venta | AF24: ● | AG24: ● | BE24: =COUNTIF(C24:BD24,"●")-((U24="●")+(W24="●")+(BD24="●")) -> 2 | BF24: =(U24="●")+(W24="●")+(BD24="●") -> 0 | BG24: =IF(BE24>0,"Cubierto",IF(BF24>0,"Con caso propuesto","Sin caso de prueba")) -> Cubierto
A25: RF-20 | B25: Garantizar que la proyección no sea negativa | AH25: ● | BE25: =COUNTIF(C25:BD25,"●")-((U25="●")+(W25="●")+(BD25="●")) -> 1 | BF25: =(U25="●")+(W25="●")+(BD25="●") -> 0 | BG25: =IF(BE25>0,"Cubierto",IF(BF25>0,"Con caso propuesto","Sin caso de prueba")) -> Cubierto
A26: RF-21 | B26: Recalcular la cobertura según el nivel de servicio | AI26: ● | AS26: ○ | BE26: =COUNTIF(C26:BD26,"●")-((U26="●")+(W26="●")+(BD26="●")) -> 1 | BF26: =(U26="●")+(W26="●")+(BD26="●") -> 0 | BG26: =IF(BE26>0,"Cubierto",IF(BF26>0,"Con caso propuesto","Sin caso de prueba")) -> Cubierto
A27: RF-22 | B27: Estimar el impacto sobre el fill rate | AJ27: ● | BE27: =COUNTIF(C27:BD27,"●")-((U27="●")+(W27="●")+(BD27="●")) -> 1 | BF27: =(U27="●")+(W27="●")+(BD27="●") -> 0 | BG27: =IF(BE27>0,"Cubierto",IF(BF27>0,"Con caso propuesto","Sin caso de prueba")) -> Cubierto
A28: RF-23 | B28: Generar el plan de compra priorizado | AG28: ○ | AK28: ● | AL28: ● | AS28: ○ | BE28: =COUNTIF(C28:BD28,"●")-((U28="●")+(W28="●")+(BD28="●")) -> 2 | BF28: =(U28="●")+(W28="●")+(BD28="●") -> 0 | BG28: =IF(BE28>0,"Cubierto",IF(BF28>0,"Con caso propuesto","Sin caso de prueba")) -> Cubierto
A29: RF-24 | B29: Descargar el plan de compra con las columnas acordadas | AM29: ● | AN29: ● | AS29: ○ | BE29: =COUNTIF(C29:BD29,"●")-((U29="●")+(W29="●")+(BD29="●")) -> 2 | BF29: =(U29="●")+(W29="●")+(BD29="●") -> 0 | BG29: =IF(BE29>0,"Cubierto",IF(BF29>0,"Con caso propuesto","Sin caso de prueba")) -> Cubierto
A30: RF-25 | B30: Visualizar el error vigente del modelo | AO30: ● | AP30: ● | AQ30: ● | BE30: =COUNTIF(C30:BD30,"●")-((U30="●")+(W30="●")+(BD30="●")) -> 3 | BF30: =(U30="●")+(W30="●")+(BD30="●") -> 0 | BG30: =IF(BE30>0,"Cubierto",IF(BF30>0,"Con caso propuesto","Sin caso de prueba")) -> Cubierto
A31: RF-26 | B31: Detectar la degradación y habilitar el reentrenamiento | AR31: ● | BE31: =COUNTIF(C31:BD31,"●")-((U31="●")+(W31="●")+(BD31="●")) -> 1 | BF31: =(U31="●")+(W31="●")+(BD31="●") -> 0 | BG31: =IF(BE31>0,"Cubierto",IF(BF31>0,"Con caso propuesto","Sin caso de prueba")) -> Cubierto
A32: RF-27 | B32: Ejecutar el ciclo mensual sin intervención técnica | AS32: ● | BC32: ○ | BE32: =COUNTIF(C32:BD32,"●")-((U32="●")+(W32="●")+(BD32="●")) -> 1 | BF32: =(U32="●")+(W32="●")+(BD32="●") -> 0 | BG32: =IF(BE32>0,"Cubierto",IF(BF32>0,"Con caso propuesto","Sin caso de prueba")) -> Cubierto
A33: RF-28 | B33: Trazar cada recomendación de compra hasta su origen | AT33: ● | BE33: =COUNTIF(C33:BD33,"●")-((U33="●")+(W33="●")+(BD33="●")) -> 1 | BF33: =(U33="●")+(W33="●")+(BD33="●") -> 0 | BG33: =IF(BE33>0,"Cubierto",IF(BF33>0,"Con caso propuesto","Sin caso de prueba")) -> Cubierto
A34: RF-29 | B34: Exigir autenticación para acceder | AU34: ● | BE34: =COUNTIF(C34:BD34,"●")-((U34="●")+(W34="●")+(BD34="●")) -> 1 | BF34: =(U34="●")+(W34="●")+(BD34="●") -> 0 | BG34: =IF(BE34>0,"Cubierto",IF(BF34>0,"Con caso propuesto","Sin caso de prueba")) -> Cubierto
A35: RF-30 | B35: Restringir funciones según el perfil del usuario | AV35: ● | BE35: =COUNTIF(C35:BD35,"●")-((U35="●")+(W35="●")+(BD35="●")) -> 1 | BF35: =(U35="●")+(W35="●")+(BD35="●") -> 0 | BG35: =IF(BE35>0,"Cubierto",IF(BF35>0,"Con caso propuesto","Sin caso de prueba")) -> Cubierto
A36: RNF-01 | B36: Tiempo de respuesta de la consulta | AW36: ● | BE36: =COUNTIF(C36:BD36,"●")-((U36="●")+(W36="●")+(BD36="●")) -> 1 | BF36: =(U36="●")+(W36="●")+(BD36="●") -> 0 | BG36: =IF(BE36>0,"Cubierto",IF(BF36>0,"Con caso propuesto","Sin caso de prueba")) -> Cubierto
A37: RNF-02 | B37: Usuarios concurrentes | AX37: ● | BE37: =COUNTIF(C37:BD37,"●")-((U37="●")+(W37="●")+(BD37="●")) -> 1 | BF37: =(U37="●")+(W37="●")+(BD37="●") -> 0 | BG37: =IF(BE37>0,"Cubierto",IF(BF37>0,"Con caso propuesto","Sin caso de prueba")) -> Cubierto
A38: RNF-03 | B38: Confidencialidad de los datos | AY38: ● | BE38: =COUNTIF(C38:BD38,"●")-((U38="●")+(W38="●")+(BD38="●")) -> 1 | BF38: =(U38="●")+(W38="●")+(BD38="●") -> 0 | BG38: =IF(BE38>0,"Cubierto",IF(BF38>0,"Con caso propuesto","Sin caso de prueba")) -> Cubierto
A39: RNF-04 | B39: Reproducibilidad de los resultados | AZ39: ● | BE39: =COUNTIF(C39:BD39,"●")-((U39="●")+(W39="●")+(BD39="●")) -> 1 | BF39: =(U39="●")+(W39="●")+(BD39="●") -> 0 | BG39: =IF(BE39>0,"Cubierto",IF(BF39>0,"Con caso propuesto","Sin caso de prueba")) -> Cubierto
A40: RNF-05 | B40: Cobertura de pruebas automatizadas | BA40: ● | BE40: =COUNTIF(C40:BD40,"●")-((U40="●")+(W40="●")+(BD40="●")) -> 1 | BF40: =(U40="●")+(W40="●")+(BD40="●") -> 0 | BG40: =IF(BE40>0,"Cubierto",IF(BF40>0,"Con caso propuesto","Sin caso de prueba")) -> Cubierto
A41: RNF-06 | B41: Compatibilidad con los archivos de SAP | BB41: ● | BE41: =COUNTIF(C41:BD41,"●")-((U41="●")+(W41="●")+(BD41="●")) -> 1 | BF41: =(U41="●")+(W41="●")+(BD41="●") -> 0 | BG41: =IF(BE41>0,"Cubierto",IF(BF41>0,"Con caso propuesto","Sin caso de prueba")) -> Cubierto
...

Sheet Pruebas por requerimiento
A1: Plan de pruebas ordenado por requerimiento
A2: Los 51 casos del plan de certificación (versión 21-09) agrupados bajo el requerimiento que verifican, en la secuencia de la toma de requerimientos. Se agregan 3 casos propuestos.
A3: Los casos propuestos (MTC_00590 a MTC_00610) cubren requerimientos que el plan no verificaba y están marcados en la columna Origen.
A5: Nº | B5: Etapa | C5: Req. | D5: Requerimiento | E5: ID caso | F5: Nombre de la prueba | G5: Tipo | H5: Estrategia | I5: Módulo a probar | J5: Pre condición | K5: Datos de prueba | L5: Resultado esperado | M5: Criterio de aceptación | N5: Automatizable | O5: Resultado | P5: Responsable | Q5: Origen
A6: 1 | B6: 1 · Ingesta y calidad de datos | C6: RF-01 | D6: Cargar las fuentes del ciclo mensual | E6: MTC_0010 | F6: Cargar archivo de venta con estructura válida | G6: Funcional | H6: Caja Negra | I6: Carga de datos | J6: Usuario autenticado con perfil planificador y archivo de venta disponible. | K6: 100.000 materiales y 6 meses de venta. Usuario: planificador.test (ambiente de pruebas). | L6: procesa el archivo y muestra fecha de carga, cantidad de registros. | M6: El resumen en pantalla debe coincidir con el número de filas del archivo de origen. | N6: SI | O6: No ejecutado | P6: Angelo Henríquez | Q6: Plan 21-09
A7: 2 | B7: 1 · Ingesta y calidad de datos | C7: RF-02 | D7: Validar la estructura de los archivos | E7: MTC_0020 | F7: Rechazar archivo con columnas obligatorias faltantes | G7: Funcional | H7: Caja Negra | I7: Carga de datos | J7: Usuario autenticado. Archivo de prueba sin la columna «Último Eslabón». | K7: Archivo venta_sin_columna.csv | L7: El sistema rechaza el archivo e indica qué columnas faltan, sin persistir ningún registro. | M7: El mensaje debe nombrar las columnas ausentes y la base no debe quedar alterada. | N7: SI | O7: No ejecutado | P7: Angelo Henríquez | Q7: Plan 21-09
A8: 3 | B8: 1 · Ingesta y calidad de datos | C8: RF-02 | D8: Validar la estructura de los archivos | E8: MTC_0030 | F8: Rechazar archivo sin registros | G8: Funcional | H8: Caja Negra | I8: Carga de datos | J8: Usuario autenticado. Archivo con encabezado y sin filas. | K8: Archivo venta_vacia.csv (solo encabezados). | L8: El sistema informa que el archivo no contiene registros y no ejecuta el proceso. | M8: Debe mostrarse un mensaje explícito y el estado de la última carga no debe cambiar. | N8: SI | O8: No ejecutado | P8: Angelo Henríquez | Q8: Plan 21-09
A9: 4 | B9: 1 · Ingesta y calidad de datos | C9: RF-03 | D9: Aplicar las reglas de calidad de datos | E9: MTC_0040 | F9: Detectar registros duplicados de material y período | G9: Funcional | H9: Caja Negra | I9: Carga de datos | J9: Usuario autenticado. Archivo con filas duplicadas intencionales. | K9: 50 materiales-período duplicados. | L9: Los duplicados se reportan en el log de calidad y se consolidan según la regla acordada con el negocio. | M9: El log debe informar la cantidad exacta de duplicados detectados y la acción aplicada. | N9: SI | O9: No ejecutado | P9: Angelo Henríquez | Q9: Plan 21-09
A10: 5 | B10: 1 · Ingesta y calidad de datos | C10: RF-03 | D10: Aplicar las reglas de calidad de datos | E10: MTC_0050 | F10: Tratar cantidades negativas en la venta | G10: Funcional | H10: Caja Negra | I10: Carga de datos | J10: Usuario autenticado. Archivo con devoluciones cargadas como cantidad negativa. | K10: 30 registros de cantidad negativa. | L10: Las cantidades negativas se marcan como atípicas, se excluyen del entrenamiento y quedan registradas en el log. | M10: Ningún registro negativo debe llegar al set de entrenamiento. | N10: SI | O10: No ejecutado | P10: Angelo Henríquez | Q10: Plan 21-09
A11: 6 | B11: 1 · Ingesta y calidad de datos | C11: RF-03 | D11: Aplicar las reglas de calidad de datos | E11: MTC_0060 | F11: Detectar períodos faltantes en la serie de un material | G11: Funcional | H11: Hibrido | I11: Carga de datos | J11: Usuario autenticado. Archivo con materiales que no venden todos los meses. | K11: 200 materiales de venta intermitente. | L11: El sistema alerta los materiales con meses sin registro y los completa con cero según la regla definida. | M11: La serie resultante debe tener 6 períodos continuos por material. | N11: SI | O11: No ejecutado | P11: Angelo Henríquez | Q11: Plan 21-09
A12: 7 | B12: 1 · Ingesta y calidad de datos | C12: RF-03 | D12: Aplicar las reglas de calidad de datos | E12: MTC_0070 | F12: Reportar material inexistente en el maestro | G12: Funcional | H12: Caja Negra | I12: Carga de datos | J12: Usuario autenticado. Archivo con códigos que no existen en el maestro de materiales. | K12: Set enmascarado con 15 códigos inexistentes. | L12: La fila se reporta como «sin maestro» en el log de calidad y no interrumpe la carga del resto del archivo. | M12: La carga debe completarse y el log debe listar los códigos no encontrados. | N12: SI | O12: No ejecutado | P12: Angelo Henríquez | Q12: Plan 21-09
A13: 8 | B13: 1 · Ingesta y calidad de datos | C13: RF-04 | D13: Controlar la recarga de un período ya procesado | E13: MTC_00100 | F13: Advertir la recarga de un período ya procesado | G13: Funcional | H13: Caja Negra | I13: Carga de datos | J13: Usuario autenticado. El período jul-2026 ya fue cargado previamente. | K13: Mismo archivo del set enmascarado, cargado por segunda vez. | L13: El sistema advierte que el período ya fue cargado y solicita confirmación antes de sobrescribir. | M13: Sin confirmación explícita del usuario no debe modificarse la carga existente. | N13: NO | O13: No ejecutado | P13: Angelo Henríquez | Q13: Plan 21-09
A14: 9 | B14: 1 · Ingesta y calidad de datos | C14: RF-05 | D14: Registrar la trazabilidad de cada carga | E14: MTC_00120 | F14: Registrar la trazabilidad de cada carga | G14: Funcional | H14: Caja Negra | I14: Carga de datos | J14: Usuario autenticado. Al menos una carga ejecutada. | K14: 100.000 materiales y 6 meses de venta. Usuario: planificador.test (ambiente de pruebas). | L14: Queda registrada la fecha, el usuario, el volumen procesado y el resultado de cada validación. | M14: El registro debe permitir reconstruir qué datos alimentaron cada proyección publicada. | N14: SI | O14: No ejecutado | P14: Angelo Henríquez | Q14: Plan 21-09
A15: 10 | B15: 2 · Preparación de datos | C15: RF-06 | D15: Normalizar cada material a su último eslabón vigente | E15: MTC_0080 | F15: Normalizar el material a su último eslabón vigente | G15: Funcional | H15: Hibrido | I15: Carga de datos | J15: Usuario autenticado. Maestro de cadena de reemplazo cargado. | K15: Set enmascarado con 40 materiales reemplazados en cadenas de 2 y 3 eslabones. | L15: Los materiales con código antecesor quedan consolidados bajo el código vigente de la cadena de reemplazo. | M15: La venta del antecesor debe sumarse a la del código vigente, sin duplicar unidades. | N15: SI | O15: No ejecutado | P15: Angelo Henríquez | Q15: Plan 21-09
A16: 11 | B16: 2 · Preparación de datos | C16: RF-06 | D16: Normalizar cada material a su último eslabón vigente | E16: MTC_0090 | F16: Conservar el código propio cuando el material no tiene antecesor | G16: Funcional | H16: Caja Negra | I16: Carga de datos | J16: Usuario autenticado. Maestro de cadena de reemplazo cargado. | K16: materiales fuera de la cadena de reemplazo. | L16: El material sin antecesor mantiene su propio código como último eslabón, sin quedar nulo. | M16: Ningún registro debe quedar con último eslabón vacío tras la normalización. | N16: SI | O16: No ejecutado | P16: Angelo Henríquez | Q16: Plan 21-09
A17: 12 | B17: 2 · Preparación de datos | C17: RF-06 | D17: Normalizar cada material a su último eslabón vigente | E17: MTC_00420 | F17: Prueba unitaria de la resolución de la cadena de reemplazo | G17: Código | H17: Caja Blanca | I17: Modelo de datos | J17: Entorno de pruebas con el maestro de reemplazo simulado. | K17: Casos: sin antecesor, cadena de 2 niveles y cadena de 3 niveles. | L17: La función devuelve el último eslabón vigente para cadenas de uno, dos y tres niveles. | M17: Las tres aserciones deben pasar y no debe producirse recursión infinita en cadenas cíclicas. | N17: SI | O17: No ejecutado | P17: Por asignar | Q17: Plan 21-09
... A59: 54 | B59: 12 · Transversal · no funcionales | C59: RNF-08 | D59: Despliegue en contenedores | E59: MTC_00610 | F59: Levantar el sistema completo con Docker Compose | G59: No Funcional | H59: Caja Negra | I59: Transversal | J59: Equipo con Docker instalado y archivo .env configurado. | K59: Repositorio del proyecto en la rama principal. | L59: El comando docker compose up levanta la base de datos y la aplicación, y la aplicación responde en el puerto 8501. | M59: Ambos servicios quedan en estado healthy. | N59: SI | O59: No ejecutado | P59: Por asignar | Q59: Propuesto
